<?xml version="1.0" ?>
<robot name="svdog2_2" xmlns:xacro="http://www.ros.org/wiki/xacro">

<xacro:include filename="$(find svdog2_2_description)/urdf/materials.xacro" />
<xacro:include filename="$(find svdog2_2_description)/urdf/svdog2_2.trans" />
<link name="base_link">
  <inertial>
    <origin xyz="-5.624212056449514e-05 0.002508800042642536 -0.009416344958760807" rpy="0 0 0"/>
    <mass value="0.07930588131469539"/>
    <inertia ixx="6.5e-05" iyy="0.000179" izz="0.000241" ixy="0.0" iyz="-0.0" ixz="-0.0"/>
  </inertial>
  <visual>
    <origin xyz="0 0 0" rpy="0 0 0"/>
    <geometry>
      <mesh filename="package://svdog2_2_description/meshes/base_link.stl" scale="0.001 0.001 0.001"/>
    </geometry>
    <material name="smooth_white"/>
  </visual>
  <collision>
    <origin xyz="0 0 0" rpy="0 0 0"/>
    <geometry>
      <mesh filename="package://svdog2_2_description/meshes/base_link.stl" scale="0.001 0.001 0.001"/>
    </geometry>
  </collision>
</link>

<link name="servo_leg_test_02_8">
  <inertial>
    <origin xyz="0.02613839119394082 -0.0010712301742271668 -0.026139027739486474" rpy="0 0 0"/>
    <mass value="0.012249665999094939"/>
    <inertia ixx="2e-06" iyy="4e-06" izz="2e-06" ixy="0.0" iyz="-0.0" ixz="1e-06"/>
  </inertial>
  <visual>
    <origin xyz="-0.054744 -0.049309 0.013641" rpy="0 0 0"/>
    <geometry>
      <mesh filename="package://svdog2_2_description/meshes/servo_leg_test_02_8.stl" scale="0.001 0.001 0.001"/>
    </geometry>
    <material name="default"/>
  </visual>
  <collision>
    <origin xyz="-0.054744 -0.049309 0.013641" rpy="0 0 0"/>
    <geometry>
      <mesh filename="package://svdog2_2_description/meshes/servo_leg_test_02_8.stl" scale="0.001 0.001 0.001"/>
    </geometry>
  </collision>
</link>

<link name="servo_leg_test_03_8">
  <inertial>
    <origin xyz="-0.013105445311555428 0.0019695981363026527 -0.013105275734626817" rpy="0 0 0"/>
    <mass value="0.0029430333024557404"/>
    <inertia ixx="0.0" iyy="1e-06" izz="0.0" ixy="0.0" iyz="0.0" ixz="-0.0"/>
  </inertial>
  <visual>
    <origin xyz="-0.090099 -0.059809 0.048997" rpy="0 0 0"/>
    <geometry>
      <mesh filename="package://svdog2_2_description/meshes/servo_leg_test_03_8.stl" scale="0.001 0.001 0.001"/>
    </geometry>
    <material name="1"/>
  </visual>
  <collision>
    <origin xyz="-0.090099 -0.059809 0.048997" rpy="0 0 0"/>
    <geometry>
      <mesh filename="package://svdog2_2_description/meshes/servo_leg_test_03_8.stl" scale="0.001 0.001 0.001"/>
    </geometry>
  </collision>
</link>

<link name="servo_leg_test_02__1__2">
  <inertial>
    <origin xyz="0.026138391193940638 -0.0010712301742272015 -0.026139027739486717" rpy="0 0 0"/>
    <mass value="0.012249665999094907"/>
    <inertia ixx="2e-06" iyy="4e-06" izz="2e-06" ixy="0.0" iyz="-0.0" ixz="1e-06"/>
  </inertial>
  <visual>
    <origin xyz="0.054856 -0.049309 0.013641" rpy="0 0 0"/>
    <geometry>
      <mesh filename="package://svdog2_2_description/meshes/servo_leg_test_02__1__2.stl" scale="0.001 0.001 0.001"/>
    </geometry>
    <material name="default"/>
  </visual>
  <collision>
    <origin xyz="0.054856 -0.049309 0.013641" rpy="0 0 0"/>
    <geometry>
      <mesh filename="package://svdog2_2_description/meshes/servo_leg_test_02__1__2.stl" scale="0.001 0.001 0.001"/>
    </geometry>
  </collision>
</link>

<link name="servo_leg_test_03__1__2">
  <inertial>
    <origin xyz="-0.013105445311555674 0.001969598136302507 -0.01310527573462756" rpy="0 0 0"/>
    <mass value="0.0029430333024557365"/>
    <inertia ixx="0.0" iyy="1e-06" izz="0.0" ixy="0.0" iyz="0.0" ixz="-0.0"/>
  </inertial>
  <visual>
    <origin xyz="0.019501 -0.059809 0.048997" rpy="0 0 0"/>
    <geometry>
      <mesh filename="package://svdog2_2_description/meshes/servo_leg_test_03__1__2.stl" scale="0.001 0.001 0.001"/>
    </geometry>
    <material name="1"/>
  </visual>
  <collision>
    <origin xyz="0.019501 -0.059809 0.048997" rpy="0 0 0"/>
    <geometry>
      <mesh filename="package://svdog2_2_description/meshes/servo_leg_test_03__1__2.stl" scale="0.001 0.001 0.001"/>
    </geometry>
  </collision>
</link>

<link name="servo_leg_test_02__1___1___1__2">
  <inertial>
    <origin xyz="0.026138391193940395 0.0010708302595121288 -0.026139027739486294" rpy="0 0 0"/>
    <mass value="0.012249665999094881"/>
    <inertia ixx="2e-06" iyy="4e-06" izz="2e-06" ixy="-0.0" iyz="0.0" ixz="1e-06"/>
  </inertial>
  <visual>
    <origin xyz="0.054856 0.044291 0.013641" rpy="0 0 0"/>
    <geometry>
      <mesh filename="package://svdog2_2_description/meshes/servo_leg_test_02__1___1___1__2.stl" scale="0.001 0.001 0.001"/>
    </geometry>
    <material name="default"/>
  </visual>
  <collision>
    <origin xyz="0.054856 0.044291 0.013641" rpy="0 0 0"/>
    <geometry>
      <mesh filename="package://svdog2_2_description/meshes/servo_leg_test_02__1___1___1__2.stl" scale="0.001 0.001 0.001"/>
    </geometry>
  </collision>
</link>

<link name="servo_leg_test_03__1___1___1__2">
  <inertial>
    <origin xyz="-0.013105445311555938 -0.0019699980510178433 -0.013105275734626574" rpy="0 0 0"/>
    <mass value="0.002943033302455784"/>
    <inertia ixx="0.0" iyy="1e-06" izz="0.0" ixy="-0.0" iyz="-0.0" ixz="-0.0"/>
  </inertial>
  <visual>
    <origin xyz="0.019501 0.054791 0.048997" rpy="0 0 0"/>
    <geometry>
      <mesh filename="package://svdog2_2_description/meshes/servo_leg_test_03__1___1___1__2.stl" scale="0.001 0.001 0.001"/>
    </geometry>
    <material name="1"/>
  </visual>
  <collision>
    <origin xyz="0.019501 0.054791 0.048997" rpy="0 0 0"/>
    <geometry>
      <mesh filename="package://svdog2_2_description/meshes/servo_leg_test_03__1___1___1__2.stl" scale="0.001 0.001 0.001"/>
    </geometry>
  </collision>
</link>

<link name="servo_leg_test_02__1___1__2">
  <inertial>
    <origin xyz="0.026138391193940166 0.0010708302595124897 -0.026139027739486294" rpy="0 0 0"/>
    <mass value="0.012249665999094921"/>
    <inertia ixx="2e-06" iyy="4e-06" izz="2e-06" ixy="-0.0" iyz="0.0" ixz="1e-06"/>
  </inertial>
  <visual>
    <origin xyz="-0.054744 0.044291 0.013641" rpy="0 0 0"/>
    <geometry>
      <mesh filename="package://svdog2_2_description/meshes/servo_leg_test_02__1___1__2.stl" scale="0.001 0.001 0.001"/>
    </geometry>
    <material name="default"/>
  </visual>
  <collision>
    <origin xyz="-0.054744 0.044291 0.013641" rpy="0 0 0"/>
    <geometry>
      <mesh filename="package://svdog2_2_description/meshes/servo_leg_test_02__1___1__2.stl" scale="0.001 0.001 0.001"/>
    </geometry>
  </collision>
</link>

<link name="servo_leg_test_03__1___1__2">
  <inertial>
    <origin xyz="-0.01310544531155644 -0.0019699980510172743 -0.013105275734626665" rpy="0 0 0"/>
    <mass value="0.002943033302455746"/>
    <inertia ixx="0.0" iyy="1e-06" izz="0.0" ixy="-0.0" iyz="-0.0" ixz="-0.0"/>
  </inertial>
  <visual>
    <origin xyz="-0.090099 0.054791 0.048997" rpy="0 0 0"/>
    <geometry>
      <mesh filename="package://svdog2_2_description/meshes/servo_leg_test_03__1___1__2.stl" scale="0.001 0.001 0.001"/>
    </geometry>
    <material name="1"/>
  </visual>
  <collision>
    <origin xyz="-0.090099 0.054791 0.048997" rpy="0 0 0"/>
    <geometry>
      <mesh filename="package://svdog2_2_description/meshes/servo_leg_test_03__1___1__2.stl" scale="0.001 0.001 0.001"/>
    </geometry>
  </collision>
</link>

<joint name="Rev49" type="revolute">
  <origin xyz="0.054744 0.049309 -0.013641" rpy="0 0 0"/>
  <parent link="base_link"/>
  <child link="servo_leg_test_02_8"/>
  <axis xyz="0.0 -1.0 -0.0"/>
  <limit upper="0.523599" lower="-0.523599" effort="100" velocity="100"/>
</joint>

<joint name="Rev50" type="revolute">
  <origin xyz="0.035355 0.0105 -0.035356" rpy="0 0 0"/>
  <parent link="servo_leg_test_02_8"/>
  <child link="servo_leg_test_03_8"/>
  <axis xyz="-0.0 -1.0 -0.0"/>
  <limit upper="0.523599" lower="-0.523599" effort="100" velocity="100"/>
</joint>

<joint name="Rev51" type="revolute">
  <origin xyz="-0.054856 0.049309 -0.013641" rpy="0 0 0"/>
  <parent link="base_link"/>
  <child link="servo_leg_test_02__1__2"/>
  <axis xyz="0.0 -1.0 -0.0"/>
  <limit upper="0.523599" lower="-0.523599" effort="100" velocity="100"/>
</joint>

<joint name="Rev52" type="revolute">
  <origin xyz="0.035355 0.0105 -0.035356" rpy="0 0 0"/>
  <parent link="servo_leg_test_02__1__2"/>
  <child link="servo_leg_test_03__1__2"/>
  <axis xyz="-0.0 -1.0 -0.0"/>
  <limit upper="0.523599" lower="-0.523599" effort="100" velocity="100"/>
</joint>

<joint name="Rev53" type="revolute">
  <origin xyz="-0.054856 -0.044291 -0.013641" rpy="0 0 0"/>
  <parent link="base_link"/>
  <child link="servo_leg_test_02__1___1___1__2"/>
  <axis xyz="-0.0 1.0 0.0"/>
  <limit upper="0.523599" lower="-0.523599" effort="100" velocity="100"/>
</joint>

<joint name="Rev54" type="revolute">
  <origin xyz="0.035355 -0.0105 -0.035356" rpy="0 0 0"/>
  <parent link="servo_leg_test_02__1___1___1__2"/>
  <child link="servo_leg_test_03__1___1___1__2"/>
  <axis xyz="-0.0 1.0 -0.0"/>
  <limit upper="0.523599" lower="-0.523599" effort="100" velocity="100"/>
</joint>

<joint name="Rev55" type="revolute">
  <origin xyz="0.054744 -0.044291 -0.013641" rpy="0 0 0"/>
  <parent link="base_link"/>
  <child link="servo_leg_test_02__1___1__2"/>
  <axis xyz="-0.0 1.0 0.0"/>
  <limit upper="0.523599" lower="-0.523599" effort="100" velocity="100"/>
</joint>

<joint name="Rev56" type="revolute">
  <origin xyz="0.035355 -0.0105 -0.035356" rpy="0 0 0"/>
  <parent link="servo_leg_test_02__1___1__2"/>
  <child link="servo_leg_test_03__1___1__2"/>
  <axis xyz="-0.0 1.0 0.0"/>
  <limit upper="0.523599" lower="-0.523599" effort="100" velocity="100"/>
</joint>

</robot>
