<?xml version="1.0" ?>
<!-- =================================================================================== -->
<!-- |    This document was autogenerated by xacro from svdog2_2.xacro                 | -->
<!-- |    EDITING THIS FILE BY HAND IS NOT RECOMMENDED                                 | -->
<!-- =================================================================================== -->
<robot name="svdog2_2">
  <material name="default">
    <color rgba="0.700 0.700 0.700 1.000"/>
  </material>
  <transmission name="Rev49_tran">
    <type>transmission_interface/SimpleTransmission</type>
    <joint name="Rev49">
      <hardwareInterface>hardware_interface/EffortJointInterface</hardwareInterface>
    </joint>
    <actuator name="Rev49_actr">
      <hardwareInterface>hardware_interface/EffortJointInterface</hardwareInterface>
      <mechanicalReduction>1</mechanicalReduction>
    </actuator>
  </transmission>
  <transmission name="Rev50_tran">
    <type>transmission_interface/SimpleTransmission</type>
    <joint name="Rev50">
      <hardwareInterface>hardware_interface/EffortJointInterface</hardwareInterface>
    </joint>
    <actuator name="Rev50_actr">
      <hardwareInterface>hardware_interface/EffortJointInterface</hardwareInterface>
      <mechanicalReduction>1</mechanicalReduction>
    </actuator>
  </transmission>
  <transmission name="Rev51_tran">
    <type>transmission_interface/SimpleTransmission</type>
    <joint name="Rev51">
      <hardwareInterface>hardware_interface/EffortJointInterface</hardwareInterface>
    </joint>
    <actuator name="Rev51_actr">
      <hardwareInterface>hardware_interface/EffortJointInterface</hardwareInterface>
      <mechanicalReduction>1</mechanicalReduction>
    </actuator>
  </transmission>
  <transmission name="Rev52_tran">
    <type>transmission_interface/SimpleTransmission</type>
    <joint name="Rev52">
      <hardwareInterface>hardware_interface/EffortJointInterface</hardwareInterface>
    </joint>
    <actuator name="Rev52_actr">
      <hardwareInterface>hardware_interface/EffortJointInterface</hardwareInterface>
      <mechanicalReduction>1</mechanicalReduction>
    </actuator>
  </transmission>
  <transmission name="Rev53_tran">
    <type>transmission_interface/SimpleTransmission</type>
    <joint name="Rev53">
      <hardwareInterface>hardware_interface/EffortJointInterface</hardwareInterface>
    </joint>
    <actuator name="Rev53_actr">
      <hardwareInterface>hardware_interface/EffortJointInterface</hardwareInterface>
      <mechanicalReduction>1</mechanicalReduction>
    </actuator>
  </transmission>
  <transmission name="Rev54_tran">
    <type>transmission_interface/SimpleTransmission</type>
    <joint name="Rev54">
      <hardwareInterface>hardware_interface/EffortJointInterface</hardwareInterface>
    </joint>
    <actuator name="Rev54_actr">
      <hardwareInterface>hardware_interface/EffortJointInterface</hardwareInterface>
      <mechanicalReduction>1</mechanicalReduction>
    </actuator>
  </transmission>
  <transmission name="Rev55_tran">
    <type>transmission_interface/SimpleTransmission</type>
    <joint name="Rev55">
      <hardwareInterface>hardware_interface/EffortJointInterface</hardwareInterface>
    </joint>
    <actuator name="Rev55_actr">
      <hardwareInterface>hardware_interface/EffortJointInterface</hardwareInterface>
      <mechanicalReduction>1</mechanicalReduction>
    </actuator>
  </transmission>
  <transmission name="Rev56_tran">
    <type>transmission_interface/SimpleTransmission</type>
    <joint name="Rev56">
      <hardwareInterface>hardware_interface/EffortJointInterface</hardwareInterface>
    </joint>
    <actuator name="Rev56_actr">
      <hardwareInterface>hardware_interface/EffortJointInterface</hardwareInterface>
      <mechanicalReduction>1</mechanicalReduction>
    </actuator>
  </transmission>
  <link name="base_link">
    <inertial>
      <origin rpy="0 0 0" xyz="-5.624212056449514e-05 0.002508800042642536 -0.009416344958760807"/>
      <mass value="0.257"/>
      <inertia ixx="6.5e-05" ixy="0.0" ixz="-0.0" iyy="0.000179" iyz="-0.0" izz="0.000241"/>
    </inertial>
    <visual>
      <origin rpy="0 0 0" xyz="0 0 0"/>
      <geometry>
        <mesh filename="package://meshes/base_link.stl" scale="0.001 0.001 0.001"/>
      </geometry>
      <material name="default"/>
    </visual>
    <collision>
      <origin rpy="0 0 0" xyz="0 0 0"/>
      <geometry>
        <mesh filename="package://meshes/base_link.stl" scale="0.001 0.001 0.001"/>
      </geometry>
    </collision>
  </link>
  <link name="servo_leg_test_02_8">
    <inertial>
      <origin rpy="0 0 0" xyz="0.02613839119394082 -0.0010712301742271668 -0.026139027739486474"/>
      <mass value="0.017"/>
      <inertia ixx="2e-06" ixy="0.0" ixz="1e-06" iyy="4e-06" iyz="-0.0" izz="2e-06"/>
    </inertial>
    <visual>
      <origin rpy="0 0 0" xyz="-0.054744 -0.049309 0.013641"/>
      <geometry>
        <mesh filename="package://meshes/servo_leg_test_02_8.stl" scale="0.001 0.001 0.001"/>
      </geometry>
      <material name="default"/>
    </visual>
    <collision>
      <origin rpy="0 0 0" xyz="-0.054744 -0.049309 0.013641"/>
      <geometry>
        <mesh filename="package://meshes/servo_leg_test_02_8.stl" scale="0.001 0.001 0.001"/>
      </geometry>
    </collision>
  </link>
  <link name="servo_leg_test_03_8">
    <inertial>
      <origin rpy="0 0 0" xyz="-0.013105445311555428 0.0019695981363026527 -0.013105275734626817"/>
      <mass value="0.004"/>
      <inertia ixx="0.0" ixy="0.0" ixz="-0.0" iyy="1e-06" iyz="0.0" izz="0.0"/>
    </inertial>
    <visual>
      <origin rpy="0 0 0" xyz="-0.090099 -0.059809 0.048997"/>
      <geometry>
        <mesh filename="package://meshes/servo_leg_test_03_8.stl" scale="0.001 0.001 0.001"/>
      </geometry>
      <material name="default"/>
    </visual>
    <collision>
      <origin rpy="0 0 0" xyz="-0.090099 -0.059809 0.048997"/>
      <geometry>
        <mesh filename="package://meshes/servo_leg_test_03_8.stl" scale="0.001 0.001 0.001"/>
      </geometry>
    </collision>
  </link>
  <link name="servo_leg_test_02__1__2">
    <inertial>
      <origin rpy="0 0 0" xyz="0.026138391193940638 -0.0010712301742272015 -0.026139027739486717"/>
      <mass value="0.017"/>
      <inertia ixx="2e-06" ixy="0.0" ixz="1e-06" iyy="4e-06" iyz="-0.0" izz="2e-06"/>
    </inertial>
    <visual>
      <origin rpy="0 0 0" xyz="0.054856 -0.049309 0.013641"/>
      <geometry>
        <mesh filename="package://meshes/servo_leg_test_02__1__2.stl" scale="0.001 0.001 0.001"/>
      </geometry>
      <material name="default"/>
    </visual>
    <collision>
      <origin rpy="0 0 0" xyz="0.054856 -0.049309 0.013641"/>
      <geometry>
        <mesh filename="package://meshes/servo_leg_test_02__1__2.stl" scale="0.001 0.001 0.001"/>
      </geometry>
    </collision>
  </link>
  <link name="servo_leg_test_03__1__2">
    <inertial>
      <origin rpy="0 0 0" xyz="-0.013105445311555674 0.001969598136302507 -0.01310527573462756"/>
      <mass value="0.004"/>
      <inertia ixx="0.0" ixy="0.0" ixz="-0.0" iyy="1e-06" iyz="0.0" izz="0.0"/>
    </inertial>
    <visual>
      <origin rpy="0 0 0" xyz="0.019501 -0.059809 0.048997"/>
      <geometry>
        <mesh filename="package://meshes/servo_leg_test_03__1__2.stl" scale="0.001 0.001 0.001"/>
      </geometry>
      <material name="default"/>
    </visual>
    <collision>
      <origin rpy="0 0 0" xyz="0.019501 -0.059809 0.048997"/>
      <geometry>
        <mesh filename="package://meshes/servo_leg_test_03__1__2.stl" scale="0.001 0.001 0.001"/>
      </geometry>
    </collision>
  </link>
  <link name="servo_leg_test_02__1___1___1__2">
    <inertial>
      <origin rpy="0 0 0" xyz="0.026138391193940395 0.0010708302595121288 -0.026139027739486294"/>
      <mass value="0.017"/>
      <inertia ixx="2e-06" ixy="-0.0" ixz="1e-06" iyy="4e-06" iyz="0.0" izz="2e-06"/>
    </inertial>
    <visual>
      <origin rpy="0 0 0" xyz="0.054856 0.044291 0.013641"/>
      <geometry>
        <mesh filename="package://meshes/servo_leg_test_02__1___1___1__2.stl" scale="0.001 0.001 0.001"/>
      </geometry>
      <material name="default"/>
    </visual>
    <collision>
      <origin rpy="0 0 0" xyz="0.054856 0.044291 0.013641"/>
      <geometry>
        <mesh filename="package://meshes/servo_leg_test_02__1___1___1__2.stl" scale="0.001 0.001 0.001"/>
      </geometry>
    </collision>
  </link>
  <link name="servo_leg_test_03__1___1___1__2">
    <inertial>
      <origin rpy="0 0 0" xyz="-0.013105445311555938 -0.0019699980510178433 -0.013105275734626574"/>
      <mass value="0.004"/>
      <inertia ixx="0.0" ixy="-0.0" ixz="-0.0" iyy="1e-06" iyz="-0.0" izz="0.0"/>
    </inertial>
    <visual>
      <origin rpy="0 0 0" xyz="0.019501 0.054791 0.048997"/>
      <geometry>
        <mesh filename="package://meshes/servo_leg_test_03__1___1___1__2.stl" scale="0.001 0.001 0.001"/>
      </geometry>
      <material name="1"/>
    </visual>
    <collision>
      <origin rpy="0 0 0" xyz="0.019501 0.054791 0.048997"/>
      <geometry>
        <mesh filename="package://meshes/servo_leg_test_03__1___1___1__2.stl" scale="0.001 0.001 0.001"/>
      </geometry>
    </collision>
  </link>
  <link name="servo_leg_test_02__1___1__2">
    <inertial>
      <origin rpy="0 0 0" xyz="0.026138391193940166 0.0010708302595124897 -0.026139027739486294"/>
      <mass value="0.017"/>
      <inertia ixx="2e-06" ixy="-0.0" ixz="1e-06" iyy="4e-06" iyz="0.0" izz="2e-06"/>
    </inertial>
    <visual>
      <origin rpy="0 0 0" xyz="-0.054744 0.044291 0.013641"/>
      <geometry>
        <mesh filename="package://meshes/servo_leg_test_02__1___1__2.stl" scale="0.001 0.001 0.001"/>
      </geometry>
      <material name="default"/>
    </visual>
    <collision>
      <origin rpy="0 0 0" xyz="-0.054744 0.044291 0.013641"/>
      <geometry>
        <mesh filename="package://meshes/servo_leg_test_02__1___1__2.stl" scale="0.001 0.001 0.001"/>
      </geometry>
    </collision>
  </link>
  <link name="servo_leg_test_03__1___1__2">
    <inertial>
      <origin rpy="0 0 0" xyz="-0.01310544531155644 -0.0019699980510172743 -0.013105275734626665"/>
      <mass value="0.004"/>
      <inertia ixx="0.0" ixy="-0.0" ixz="-0.0" iyy="1e-06" iyz="-0.0" izz="0.0"/>
    </inertial>
    <visual>
      <origin rpy="0 0 0" xyz="-0.090099 0.054791 0.048997"/>
      <geometry>
        <mesh filename="package://meshes/servo_leg_test_03__1___1__2.stl" scale="0.001 0.001 0.001"/>
      </geometry>
      <material name="1"/>
    </visual>
    <collision>
      <origin rpy="0 0 0" xyz="-0.090099 0.054791 0.048997"/>
      <geometry>
        <mesh filename="package://meshes/servo_leg_test_03__1___1__2.stl" scale="0.001 0.001 0.001"/>
      </geometry>
    </collision>
  </link>
  <joint name="Rev49" type="revolute">
    <origin rpy="0 0 0" xyz="0.054744 0.049309 -0.013641"/>
    <parent link="base_link"/>
    <child link="servo_leg_test_02_8"/>
    <axis xyz="0.0 -1.0 -0.0"/>
    <limit effort="100" lower="-0.523599" upper="0.523599" velocity="100"/>
  </joint>
  <joint name="Rev50" type="revolute">
    <origin rpy="0 0 0" xyz="0.035355 0.0105 -0.035356"/>
    <parent link="servo_leg_test_02_8"/>
    <child link="servo_leg_test_03_8"/>
    <axis xyz="-0.0 -1.0 -0.0"/>
    <limit effort="100" lower="-0.523599" upper="0.523599" velocity="100"/>
  </joint>
  <joint name="Rev51" type="revolute">
    <origin rpy="0 0 0" xyz="-0.054856 0.049309 -0.013641"/>
    <parent link="base_link"/>
    <child link="servo_leg_test_02__1__2"/>
    <axis xyz="0.0 -1.0 -0.0"/>
    <limit effort="100" lower="-0.523599" upper="0.523599" velocity="100"/>
  </joint>
  <joint name="Rev52" type="revolute">
    <origin rpy="0 0 0" xyz="0.035355 0.0105 -0.035356"/>
    <parent link="servo_leg_test_02__1__2"/>
    <child link="servo_leg_test_03__1__2"/>
    <axis xyz="-0.0 -1.0 -0.0"/>
    <limit effort="100" lower="-0.523599" upper="0.523599" velocity="100"/>
  </joint>
  <joint name="Rev53" type="revolute">
    <origin rpy="0 0 0" xyz="-0.054856 -0.044291 -0.013641"/>
    <parent link="base_link"/>
    <child link="servo_leg_test_02__1___1___1__2"/>
    <axis xyz="-0.0 1.0 0.0"/>
    <limit effort="100" lower="-0.523599" upper="0.523599" velocity="100"/>
  </joint>
  <joint name="Rev54" type="revolute">
    <origin rpy="0 0 0" xyz="0.035355 -0.0105 -0.035356"/>
    <parent link="servo_leg_test_02__1___1___1__2"/>
    <child link="servo_leg_test_03__1___1___1__2"/>
    <axis xyz="-0.0 1.0 -0.0"/>
    <limit effort="100" lower="-0.523599" upper="0.523599" velocity="100"/>
  </joint>
  <joint name="Rev55" type="revolute">
    <origin rpy="0 0 0" xyz="0.054744 -0.044291 -0.013641"/>
    <parent link="base_link"/>
    <child link="servo_leg_test_02__1___1__2"/>
    <axis xyz="-0.0 1.0 0.0"/>
    <limit effort="100" lower="-0.523599" upper="0.523599" velocity="100"/>
  </joint>
  <joint name="Rev56" type="revolute">
    <origin rpy="0 0 0" xyz="0.035355 -0.0105 -0.035356"/>
    <parent link="servo_leg_test_02__1___1__2"/>
    <child link="servo_leg_test_03__1___1__2"/>
    <axis xyz="-0.0 1.0 0.0"/>
    <limit effort="100" lower="-0.523599" upper="0.523599" velocity="100"/>
  </joint>
</robot>
